# 不得不了解的前端异常处理

## 前言

在我们平时的开发中，总是会遇到各种各样的问题，然后去调试处理。而且我相信，在各位开发的过程中，调试占用的开发时间非常高，因为我们不仅要进行逻辑处理，还要处理相关的问题异常。所以，既然我们天天和异常打交道，就需要正确认识异常，并作出合适的异常处理就显得尤为重要了。

## 什么是异常

用直白的话来说，就是 `程序发生了意想不到的情况，这种情况影响到了程序的正确运行`。

从根本上来说，异常就是一个 `数据结构`，其保存了异常发生的相关信息，比如`错误码`和`错误信息`等。以JS为标准的内置对象Error为例，其标准属性有`name`和`message`,然而不同的浏览器厂商有自己的自定义属性，这些属性并不通用，比如Mozilla就增加了filename和stack等属性。

值得我们注意的是，错误只有被抛出，才会产生异常，不被抛出的错误不会产生异常。比如:
```js
function test(){
 console.log('start')
 new Error();
 console.log('end')
}
test();
```
这段代码不会产生任何的异常，控制台也不会有任何输出。

## 异常的分类

在我们平时的开发中，按照产生异常时我们程序是否在运行，可以把异常分为`编译时异常`和`运行时异常`。
编译时异常通常是指的我们源代码在编译成可执行代码之前产生的异常。而运行时异常是指可执行代码在被装载到内存中执行之后产生的异常。

### 编译时异常

现在前端比较火的TS，我们知道使用TS最终会被编译成可执行的JS，从而在JS Runtime中执行。TS在编译成JS时，就有可能存在编译时异常。比如:

```ts
const s:string = 123
```
相信大家了解TS的都知道，这是很明显的错误，我们在声明s时，定义它的类型为string,但是赋值了一个number。当我们在尝试编译时就会有异常抛出:
```ts
tsc a.ts
a.ts:1:7 - error TS2322: Type '123' is not assignable to type 'string'.

1 const s: string = 123;

~
Found 1 error.
```
这个异常就是编译时异常，因为我的代码还没有执行。然而并不是用了ts才会有编译时异常，我们使用的js同样会存在编译时异常。有的人可能会问，js不是解释性语言吗？是边解释边执行，没有编译环节，怎么就有编译时异常？给大家举个例子就明白了:

```js
function test(){
 console.log('start')
 await sa
 console.log('end')
}
test()
```
相信大家能看明白上面代码的错误，上面的代码由于存在语法错误。不会编译通过，因此并不会打印start，侧面证明了这是一个编译时异常。尽管js是解释性语言，也依然存在编译阶段，这是必然的。因此自然也会有编译时异常。
总体来说，编译异常可以在代码被编译成最终代码前被发现，因此对我们的伤害更小。接下来，看一下令人心生畏惧的`运行时异常`。

### 运行时异常

相信各位同学在经历了开发工作后，对运行时异常都非常的熟悉啦。众所周知的NPE(Null Pointer Exception)就是经典的运行时异常。我们看一下一个例子:
```js
function test() {
  console.log("start");
  throw 1;
  console.log("end");
}
test();
```
执行上面的代码，在控制台中会先打印出start,然后抛出异常，程序终止执行。由于异常是在运行过程中抛出的，因此是运行时异常。相对于编译时异常，运行时异常更加难以发现。上面的例子可能比较简单，但是如果我的异常是隐藏在某一个流程控制语句里面呢？程序就可能在客户的电脑走入哪个跑出异常的特殊语句中，而你的电脑走入了正常语句。这就是著名的`《在我电脑上好好的》`事件。

>注意:end没有打印,并且test没有直接弹出运行栈(而是经过异常抛出后，被垃圾回收机制回收),实际上会弹出，只是和普通的返回不一样。

## 异常的传播

有了异常，肯定就会有异常处理。但是处理异常的前提是我们得知道异常是在哪里出现的，因此，我们需要了解异常的传播。实际上，异常的传播和浏览器事件有点类似，只不过浏览器事件是作用在`DOM这样的数据结构`中,异常传播是作用在`函数调用栈`这种数据结构中，并且事件存在捕获阶段，但是异常传播没有。不同于C语言，js异常传播是自动的。不需要我们手动的一层层传递，如果一个异常没有被catch。它会沿着调用栈一层层传递直到栈空。实际上，在异常处理中有两个关键词，它们是`「throw（抛出异常）」`和`「catch（处理异常）」`。当一个异常被抛出的时候，异常的传播就开始了。异常会不断传播直到遇到`第一个catch`。如果程序员没有手动 catch，那么一般而言程序会抛出类似`「unCaughtError」`，表示发生了一个异常，并且这个异常没有被程序中的任何catch语言处理。未被捕获的异常通常会被打印在控制台上， 里面有详细的堆栈信息，从而帮助程序员快速排查问题。实际上我们的程序目标是`「避免 unCaughtError」`这种异常，而不是一般性异常。

### js处理

由于在我们的js内置的Error对象中没有code属性，只能根据message来呈现，很不方便，不是很方便，所以我们可以尝试做一下简单扩展。

```js
var oldError = Error
Error = function({ code, message, fileName, lineNumber }) {
	var error = new oldError(message, fileName, lineNumber)
  error.code = code
  return error
}
```

### 手动抛出Or自动抛出

异常既然可以有程序抛出，当然也可以由程序员主动抛出。

```js
//手动抛出
throw new Error("I'm Exception.")

//自动抛出
var a = null
a.toString()  // Thrown: TypeError: Cannot read property 'toString' of null
```

自动抛出相信我们很容易理解，毕竟在开发中，处处都有可能存在程序自动抛出异常的代码。那么，我们什么时候该主动抛出异常呢？

主动抛出的一个原则就是`我们已经预知程序不能正确进行下去`。比如我们要实现除法，首先我们要排除除数为0的情况。当除数为0的时候，我们就应该抛出异常了。当然部分同学会说我也可以返回一个特殊值，这当然也是可以的。因为每个团队标准不一致。我们在这里只讨论抛出异常的情况，当我们遇到除数为0的时候，我们应该告诉使用者，`你的输入是错误的`这种情况。

```js
function divide(a, b) {
  a = +a;
  b = +b; // 转化成数字
  if (!b) {
    // 匹配 +0, -0, NaN
    throw new Error({
      code: 1,
      message: "Invalid dividend " + b,
    });
  }
  if (Number.isNaN(a)) {
    // 匹配 NaN
    throw new Error({
      code: 2,
      message: "Invalid divisor " + a,
    });
  }
  return a / b;
}
```
上面代码会在两种情况下抛出异常，告诉调用者你的输入是错误的。由于这两个异常都是程序员自动手动抛出的，因此是 **「可预知的异常」**。
刚才也说了，我们也可以通过返回值来区分异常输入。我们来看下返回值输入是什么，以及和异常有什么关系。

### 异常or返回

如果我们是基于异常形式（遇到不能处理的输入就抛出异常）。当有代码调用 divide 的时候，需要自己 catch。

```js
function t() {
  try {
    divide("foo", "bar");
  } catch (err) {
    if (err.code === 1) {
      return console.log("被除数必须是除0之外的数");
    }
    if (err.code === 2) {
      return console.log("除数必须是数字");
    }
    throw new Error("不可预知的错误");
  }
}
```
然而就像我们在上面说的，divide 函数设计的时候，也完全可以不用异常，而是使用返回值来区分。

```js
function divide(a, b) {
  a = +a;
  b = +b; // 转化成数字
  if (!b) {
    // 匹配 +0, -0, NaN
    return new Error({
      code: 1,
      message: "Invalid dividend " + b,
    });
  }
  if (Number.isNaN(a)) {
    // 匹配 NaN
    return new Error({
      code: 2,
      message: "Invalid divisor " + a,
    });
  }
  return a / b;
}
```
当然，我们调用时处理方式也要做出相应改变

```js
function t() {
  const res = divide("foo", "bar");

  if (res.code === 1) {
    return console.log("被除数必须是除0之外的数");
  }
  if (res.code === 2) {
    return console.log("除数必须是数字");
  }
  return new Error("不可预知的错误");
}
```
这种函数设计和抛出异常的设计方式从功能上是一样的，只是告诉调用方的方式不同。如果你选择第二种，而不是抛出异常，那么实际上需要调用方书写额外的代码，用来区分正常情况和异常情况，这并不是一种良好的变成习惯。

然而在 Go 等返回值可以为复数的语言中，我们无需使用上面蹩脚的方式，而是可以：
```go
res, err := divide("foo", "bar");
if err != nil {
    log.Fatal(err)
}
```
这是和 Java 和 JS 等语言使用 try catch 不一样的地方，Go 是通过 panic recover defer 机制来进行异常处理的。感兴趣的可以去看看 Go 源码关于错误测试部分。

可能大家对 Go 不太熟悉。没关系，我们继续看下 shell。实际上 shell 也是通过返回值来处理异常，我们可以通过 $? 拿到上一个命令的返回值，这本质上也是一种调用栈的传播行为，而是通过返回值而不是捕获来处理异常。

>作为函数返回值处理和 try catch 一样，这是语言的设计者和开发者共同决定的一件事情。

上面提到了异常传播是作用在「函数调用栈」上的。当一个异常发生时，岂会沿着函数调用栈逐层返回，直到第一个 catch 语句。当然 catch 内部仍然可能触发异常（自动或手动）。如果 catch 语句内部发生了异常，也一样会沿着其函数调用栈继续执行上述逻辑，专业术语是 **「stack unwinding」**。

>实际上并不是所有的语言都会进行 stack unwinding，这个我们会在接下来的《运行时异常可以恢复么？》部分讲解。


![](http://img.stallezhou.cn/blog/exception.png)

我们使用伪代码来实现一下:
```js
function exceptionBubble(err,fn){
if (fn.hasCatchBlock()) {
    runCatchCode(error);
  }
  if (callstack.isNotEmpty()) {
    bubble(error, callstack.pop());
  }
}
```

>从我们的伪代码可以看出所谓的stack unwinding其实就是callstack.pop()

上面所有的就是异常传播，也没什么大不了的。

## 异常处理

我们已经知道了异常传播的方式，接下来，我们就需要对异常进行相应的处理了。那应该怎样处理异常呢？

我们先看一个例子:
```js
function a() {
  b();
}
function b() {
  c();
}
function c() {
  throw new Error("an error");
}
a();
```

我们在chrome控制台中执行上面代码，会得到如下输出:
![](http://img.stallezhou.cn/blog/exception_1.jpg)

我们可以清楚地看到函数的调用关系。即错误发生在 c 中发生的，而 c 是 b 调用的，b 是 a 调用的。这个函数调用栈是为了方便开发者定位问题而存在的。

上面的代码，我们并没有 catch 错误，因此上面才会有 `「uncaught Error」`。

那么如果我们 catch 会发生什么变化呢？catch 会对结果产生什么样的影响？在 a、b、c 中 catch 的效果是一样的吗？

我们分别看下:
```js
function a() {
  b();
}
function b() {
  c();
}
function c() {
  try {
    throw new Error("an error");
  } catch (err) {
    console.log(err);
  }
}
a();
```

我们将上面的代码放到 chrome 中执行，会在控制台显示如下输出：

![](http://img.stallezhou.cn/blog/exception_2.jpg)

可以看到，此时已经没有「uncaught Error」了，仅仅在控制台显示了标准输出，而非错误输出。然而更重要的是，如果我们没有 catch，后面的同步代码将不会继续执行。

比如在 c 的 throw 下面增加一行代码，这行代码是无法被执行的，**无论这个错误有没有被捕获**。

```JS
function c() {
  try {
    throw new Error("an error");
    console.log("will never run");
  } catch (err) {
    console.log(err);
  }
}
```
我们将 catch 移动到 b 中试试看。
```js
function a() {
  b();
}
function b() {
  try {
    c();
  } catch (err) {
    console.log(err);
  }
}
function c() {
  throw new Error("an error");
}

a();
```
在这个例子中，和上面在 c 中捕获没有什么本质不同，其实放到 a 中捕获也是一样，这里不再贴代码了，感兴趣的自己试下。

既然处于函数调用栈顶部的函数报错，其函数调用栈下方的任意代码都可以进行捕获，并且效果没有本质不同，那么问题来了，我们到底应该在哪里进行错误处理呢？

答案是责任链模式。我们先来简单介绍一下责任链模式。

假如Tony要请假,公司请假制度如下:
* 如果请假天数小于等于 1 天，则主管同意即可；
* 如果请假天数大于 1 天，但是小于等于 3 天，则需要 CTO 同意；
* 如果请假天数大于 3 天，则需要老板同意。

![](http://img.stallezhou.cn/blog/exception_3.svg)

这就是一个典型的责任链模式。谁有责任干什么事情是确定的，不要做自己能力范围之外的事情。比如主管不要去同意大于一天的审核。

举个例子，假设我们的应用有三个异常处理类，它们分别是：用户输入错误、网络错误和类型错误。如下代码，当代码执行的时候会报错一个用户输入异常。这个异常没有被 C 捕获，会 unwind stack 到 b，而 b 中 catch 到这个错误之后，通过查看 code 值判断其可以被处理，于是打印 I can handle this。

```js
function a() {
  try {
    b();
  } catch (err) {
    if (err.code === "NETWORK_ERROR") {
      return console.log("I can handle this");
    }
    // can't handle, pass it down
    throw err;
  }
}
function b() {
  try {
    c();
  } catch (err) {
    if (err.code === "INPUT_ERROR") {
      return console.log("I can handle this");
    }
    // can't handle, pass it down
    throw err;
  }
}
function c() {
  throw new Error({
    code: "INPUT_ERROR",
    message: "an error",
  });
}

a();
```
而如果 c 中抛出识别的异常，比如网络异常，那么 b 是无法处理的，虽然 b catch 住了，但是由于你无法处理，因此一个好的做法是继续抛出异常，而不是`吞没`异常。不要畏惧错误，抛出它。`只有没被捕获的异常才是可怕的` ，如果一个错误可以被捕获并得到正确处理，它就不可怕。比如:

```js
function a() {
  try {
    b();
  } catch (err) {
    if (err.code === "NETWORK_ERROR") {
      return console.log("I can handle this");
    }
    // can't handle, pass it down
    throw err;
  }
}
function b() {
  try {
    c();
  } catch (err) {
    if (err.code === "INPUT_ERROR") {
      return console.log("I can handle this");
    }
  }
}
function c() {
  throw new Error({
    code: "NETWORK_ERROR",
    message: "an error",
  });
}

a();
```
如上代码不会有任何异常被抛出，它被完全吞没了，这对我们调试问题简直是灾难。因此切记 **「不要吞没你不能处理的异常」**。正确的做法应该是上面讲的 **「只捕获你可以处理的异常，将你不能处理的异常抛出来」**，这就是责任链模式的典型应用。

这只是一个简单的例子，就足以绕半天。实际业务肯定比这个复杂多得多。因此异常处理绝对不是一件容易的事。

如果说谁来处理是一件困难的事情，那么在异步中决定谁来处理异常就是难上加难，我们来看下。

## 同步与异步

同步异步一直是前端难以跨域的坎，对于异常处理也是一样。以 NodeJS 中用的比较多的 **「读取文件」API** 为例。它有两个版本，一个是异步，一个是同步。同步读取仅仅应该被用在没了这个文件无法进行下去的时候，比如读取一个配置文件，而不应该再比如浏览器中读取用户磁盘上的一张图片等，这样会造成主线程阻塞，导致浏览器卡死。
```js
// 异步读取文件
fs.readFileSync();
// 同步读取文件
fs.readFile();
```

当我们试图 **「同步」** 读取一个不存在的文件的时候，会抛出以下异常:
```js
fs.readFileSync('something-not-exist.txt');
console.log('前端随手记');
Thrown:
Error: ENOENT: no such file or directory, open 'something-not-exist.txt'
    at Object.openSync (fs.js:446:3)
    at Object.readFileSync (fs.js:348:35) {
  errno: -2,
  syscall: 'open',
  code: 'ENOENT',
  path: 'something-not-exist.txt'
}
```

并且 **前端随手记**是不会被打印出来的，这个比较好理解，我们上面已经解释过了。
而如果以异步的方式：
```js
fs.readFile('something-not-exist.txt', (err, data) => {if(err) {throw err}});
console.log('前端随手记')
lucifer
undefined
Thrown:
[Error: ENOENT: no such file or directory, open 'something-not-exist.txt'] {
  errno: -2,
  code: 'ENOENT',
  syscall: 'open',
  path: 'something-not-exist.txt'
}
```
**前端随手记**是会被打印出来的。
其本质在于 **fs.readFile** 已经调用成功，并从函数调用栈返回并执行到下一行打印语句。因此错误发生的时候，调用栈是空的，这一点可以从上面的错误堆栈信息中看出来。

而 try catch 的作用仅仅是捕获当前调用栈的错误，因此异步的错误是无法捕获的，比如：
```js
try {
  fs.readFile("something-not-exist.txt", (err, data) => {
    if (err) {
      throw err;
    }
  });
} catch (err) {
  console.log("catching an error");
}
```
上面的 **catching an error** 不会被打印，因为错误抛出的时候，调用栈中不包含这个 catch 语句，而仅仅在执行 **fs.readFile** 的时候才会。

如果我们换成同步读取文件：
```js
try {
  fs.readFileSync("something-not-exist.txt");
} catch (err) {
  console.log("catching an error");
}
```
上面的代码会打印 **catching an error**，因为读取文件被同步发起，文件返回之前线程会被挂起，当线程恢复执行的时候，**fs.readFileSync** 仍然在函数调用栈中，因此 **fs.readFileSync** 产生的异常会冒泡到 catch 语句中。**
简单来说，`「异步产生的错误不能用 try catch 捕获，而要使用回调捕获」`。
如果你非要用 **try catch** 来捕获，则可以使用 `async await` 来包装异步语句，将异步语法转换成同步语法的形式，但这个异步语句必须是一个 `Promise`类型才能使用 `async await` 包装。

```js
rejectIn = (ms) =>
  new Promise((_, r) => {
    setTimeout(() => {
      r(1);
    }, ms);
  });
async function t() {
  try {
    await rejectIn(0);
  } catch (err) {
    console.log("catching an error", err);
  }
}

t();
```
而如果我们使用 babel 转义下，会发现 try catch 不见了，变成了 switch case语句。这就是 try catch 可以捕获异常异常的原因，仅此而已。

![](http://img.stallezhou.cn/blog/exception_4.png)

>虽然浏览器并不像 babel 转义这般实现，但是至少我们明白了一点，目前的 try catch 的作用机制是无法捕获异步异常的。

异步的错误处理推荐使用容器包装，比如 Promise。然后使用 catch 进行处理。实际上 Promise 的 catch 和 try catch 的 catch 有很多相似的地方，大家可以类比过去。

和同步处理一样，很多原则都是通用的。比如异步也不要去吞没异常。下面的代码是不好的，因为它吞没了 **「它不能处理的」**异常。

```js
var p = Promise.reject(1)
p.catch(() => {})
```
更合适的做法应该类似这种：
```js
var p = Promise.reject(1)
p.catch(err => {
  if(err === 1) {
    return console.log('I can handle this')
  }
  throw err
})

```

## 能否彻底消除运行时异常？

我觉得大家目前都是 **过分依赖运行时，而严重忽略编译时**,只会或者只愿意改运行时的异常，不太愿意处理编译时的异常。我见过很多程序，如果不运行，根本不知道程序是怎么走的，每个变量的 shape 是什么，怪不得处处都可以看到打印语句。我相信你一定对此感同身受。也许你是写出这种代码的人，也许你是帮别人擦屁股的人。为什么会这样？就是因为大家过分依赖运行时。`TypeScript` 的出现很大程度上改变了这一点，前提是你用的是 `TypeScript` 而不是 `AnyScript`。其实 eslint 以及 stylint 对此也有贡献，毕竟他们是静态分析工具。
我强烈建议将异常保留在编译时，而不是运行时。不妨极端一点来看：加入所有的异常都在编译时发生，而一定不会在运行时发生。那么我们是不是就可以 **「信心满满」**地对应用进行重构？

幸运的事，我们能够做到。只不过如果当前语言做不到的话，则需要对现有的语言体系进行改造。这种改造成本真的很大，不仅仅是 API，编程模型也发生了翻天覆地的变化，不然函数时也不会这么多年都没有得到普及。

## 运行时异常可以恢复吗？

最后要讨论的一个主题是运行时异常是否可以恢复。先来解释一下，什么是运行时异常的恢复。还是用上面的例子：
```js
function test() {
  console.log("start");
  throw 1;
  console.log("end");
}
test();
```
我们知道无论如何都无法打印 end，即使你 catch 了也无济于事。

如果我想让它可以打印呢？我想让程序面对异常可以自己 recover 怎么办？我已经捕获这个错误，并且我确信我可以处理，让流程继续走下去，如果有能力做到这个，这个就是 **「运行时异常恢复」**。

遗憾地告诉你，目前没有任何一个引擎可以做到这一点。


## 小结

本片文章中我们学习了异常以及异常传播、处理等。但是目前我们需要走的路还很长。望各位同学认真学习，不负韶华。
